ERROR:root:Critical error: Data corruption
ERROR:root:Exception occurred
Traceback (most recent call last):
  File "d:\Hackathon\Crasheye_backend\Test\new_try\generate_crash.py", line 35, in <module>
    generate_random_crash()
  File "d:\Hackathon\Crasheye_backend\Test\new_try\generate_crash.py", line 29, in generate_random_crash
    critical_error()
  File "d:\Hackathon\Crasheye_backend\Test\new_try\generate_crash.py", line 19, in critical_error
    raise Exception("Data corruption")
Exception: Data corruption
